2023-10-06 08:51:28,520 - DEBUG - Using selector: EpollSelector
2023-10-06 08:51:41,676 - INFO - [Serveur] fonction prendre_commande utilisée au temps 13.156798601150513
2023-10-06 08:51:42,678 - INFO - [Pic] fonction ajouter utilisée au temps 14.15903902053833
2023-10-06 08:51:42,679 - INFO - [Serveur] fonction prendre_commande utilisée au temps 14.159425497055054
2023-10-06 08:51:42,679 - INFO - [Pic] fonction retirer utilisée au temps 14.15970754623413
2023-10-06 08:51:43,680 - INFO - [Pic] fonction ajouter utilisée au temps 15.16054081916809
2023-10-06 08:51:43,680 - INFO - [Serveur] fonction prendre_commande utilisée au temps 15.16110372543335
2023-10-06 08:51:43,681 - INFO - [Barman] fonction prepare utilisée au temps 15.161591053009033
2023-10-06 08:51:43,681 - INFO - [Bar] fonction ajouter utilisée au temps 15.161980152130127
2023-10-06 08:51:43,682 - INFO - [Pic] fonction retirer utilisée au temps 15.162335872650146
2023-10-06 08:51:44,683 - INFO - [Pic] fonction ajouter utilisée au temps 16.163167476654053
2023-10-06 08:51:44,683 - INFO - [Serveur] fonction prendre_commande utilisée au temps 16.16367220878601
2023-10-06 08:51:44,683 - INFO - [Barman] fonction prepare utilisée au temps 16.16409683227539
2023-10-06 08:51:44,684 - INFO - [Bar] fonction ajouter utilisée au temps 16.1644024848938
2023-10-06 08:51:44,684 - INFO - [Pic] fonction retirer utilisée au temps 16.16471576690674
2023-10-06 08:51:45,681 - INFO - [Bar] fonction retirer utilisée au temps 17.161520957946777
2023-10-06 08:51:45,681 - INFO - [Serveur] fonction servir utilisée au temps 17.16203498840332
2023-10-06 08:51:45,682 - INFO - [Bar] fonction retirer utilisée au temps 17.162525415420532
2023-10-06 08:51:45,682 - INFO - [Serveur] fonction servir utilisée au temps 17.163032054901123
2023-10-06 08:51:45,684 - INFO - [Pic] fonction ajouter utilisée au temps 17.164987802505493
2023-10-06 08:51:45,685 - INFO - [Barman] fonction prepare utilisée au temps 17.165558099746704
2023-10-06 08:51:45,685 - INFO - [Bar] fonction ajouter utilisée au temps 17.16585087776184
2023-10-06 08:51:45,686 - INFO - [Pic] fonction retirer utilisée au temps 17.166216611862183
2023-10-06 08:51:46,686 - INFO - [Barman] fonction prepare utilisée au temps 18.16704821586609
2023-10-06 08:51:46,687 - INFO - [Bar] fonction ajouter utilisée au temps 18.16725206375122
2023-10-06 08:51:47,684 - INFO - [Bar] fonction retirer utilisée au temps 19.164708614349365
2023-10-06 08:51:47,685 - INFO - [Serveur] fonction servir utilisée au temps 19.165269136428833
2023-10-06 08:51:47,685 - INFO - [Bar] fonction retirer utilisée au temps 19.165988445281982
2023-10-06 08:51:47,686 - INFO - [Serveur] fonction servir utilisée au temps 19.166515350341797
2023-10-06 09:12:59,116 - ERROR - Task exception was never retrieved
future: <Task finished name='Task-3' coro=<Serveur.servir() done, defined at /home/ibotcazou/Bureau/Master_data_science/Master2_datascience/Informatique_charbonel/probleme_bar_cocktails/V2_asyncio/bar_asyncio.py:134> exception=SystemExit()>
Traceback (most recent call last):
  File "/usr/lib/python3.10/asyncio/runners.py", line 44, in run
    return loop.run_until_complete(main)
  File "/usr/lib/python3.10/asyncio/base_events.py", line 636, in run_until_complete
    self.run_forever()
  File "/usr/lib/python3.10/asyncio/base_events.py", line 603, in run_forever
    self._run_once()
  File "/usr/lib/python3.10/asyncio/base_events.py", line 1871, in _run_once
    event_list = self._selector.select(timeout)
  File "/usr/lib/python3.10/selectors.py", line 469, in select
    fd_event_list = self._selector.poll(timeout, max_ev)
KeyboardInterrupt

During handling of the above exception, another exception occurred:

Traceback (most recent call last):
  File "/home/ibotcazou/Bureau/Master_data_science/Master2_datascience/Informatique_charbonel/probleme_bar_cocktails/V2_asyncio/bar_asyncio.py", line 140, in servir
    await asyncio.sleep(self.bar.tp + self.pic.tc ) # Attendre un peu la commande va arriver sur le bar
  File "/usr/lib/python3.10/asyncio/tasks.py", line 605, in sleep
    return await future
asyncio.exceptions.CancelledError

During handling of the above exception, another exception occurred:

Traceback (most recent call last):
  File "/usr/lib/python3.10/asyncio/runners.py", line 47, in run
    _cancel_all_tasks(loop)
  File "/usr/lib/python3.10/asyncio/runners.py", line 63, in _cancel_all_tasks
    loop.run_until_complete(tasks.gather(*to_cancel, return_exceptions=True))
  File "/usr/lib/python3.10/asyncio/base_events.py", line 636, in run_until_complete
    self.run_forever()
  File "/usr/lib/python3.10/asyncio/base_events.py", line 603, in run_forever
    self._run_once()
  File "/usr/lib/python3.10/asyncio/base_events.py", line 1909, in _run_once
    handle._run()
  File "/usr/lib/python3.10/asyncio/events.py", line 80, in _run
    self._context.run(self._callback, *self._args)
  File "/home/ibotcazou/Bureau/Master_data_science/Master2_datascience/Informatique_charbonel/probleme_bar_cocktails/V2_asyncio/bar_asyncio.py", line 151, in servir
    sys.exit()
SystemExit
