2023-10-04 20:57:53,015 - DEBUG - Using selector: EpollSelector
2023-10-04 20:57:58,265 - INFO - [Serveur] fonction prendre_commande utilisée au temps 5.250476837158203
2023-10-04 20:58:16,052 - ERROR - Task exception was never retrieved
future: <Task finished name='Task-1' coro=<main() done, defined at /home/ibotcazou/Bureau/Master_data_science/Master2_datascience/Informatique_charbonel/probleme_bar_cocktails/V2_asyncio/./cocktail_asyncio.py:9> exception=KeyboardInterrupt()>
Traceback (most recent call last):
  File "/home/ibotcazou/Bureau/Master_data_science/Master2_datascience/Informatique_charbonel/probleme_bar_cocktails/V2_asyncio/./cocktail_asyncio.py", line 40, in <module>
    asyncio.run(main())
  File "/usr/lib/python3.10/asyncio/runners.py", line 47, in run
    _cancel_all_tasks(loop)
  File "/usr/lib/python3.10/asyncio/runners.py", line 63, in _cancel_all_tasks
    loop.run_until_complete(tasks.gather(*to_cancel, return_exceptions=True))
  File "/usr/lib/python3.10/asyncio/base_events.py", line 636, in run_until_complete
    self.run_forever()
  File "/usr/lib/python3.10/asyncio/base_events.py", line 603, in run_forever
    self._run_once()
  File "/usr/lib/python3.10/asyncio/base_events.py", line 1909, in _run_once
    handle._run()
  File "/usr/lib/python3.10/asyncio/events.py", line 80, in _run
    self._context.run(self._callback, *self._args)
  File "/home/ibotcazou/Bureau/Master_data_science/Master2_datascience/Informatique_charbonel/probleme_bar_cocktails/V2_asyncio/./cocktail_asyncio.py", line 35, in main
    await asyncio.gather(*tasks3) #gère la concurrence
  File "/usr/lib/python3.10/asyncio/runners.py", line 44, in run
    return loop.run_until_complete(main)
  File "/usr/lib/python3.10/asyncio/base_events.py", line 636, in run_until_complete
    self.run_forever()
  File "/usr/lib/python3.10/asyncio/base_events.py", line 603, in run_forever
    self._run_once()
  File "/usr/lib/python3.10/asyncio/base_events.py", line 1909, in _run_once
    handle._run()
  File "/usr/lib/python3.10/asyncio/events.py", line 80, in _run
    self._context.run(self._callback, *self._args)
  File "/home/ibotcazou/Bureau/Master_data_science/Master2_datascience/Informatique_charbonel/probleme_bar_cocktails/V2_asyncio/bar_asyncio.py", line 136, in servir
    message = sys.stdin.readline()
KeyboardInterrupt
