2023-10-06 09:15:59,998 - DEBUG - Using selector: EpollSelector
2023-10-06 09:16:07,029 - INFO - [Serveur] fonction prendre_commande utilisée au temps 7.030911684036255
2023-10-06 09:16:08,030 - INFO - [Pic] fonction ajouter utilisée au temps 8.032851457595825
2023-10-06 09:16:08,031 - INFO - [Serveur] fonction prendre_commande utilisée au temps 8.033306360244751
2023-10-06 09:16:08,031 - INFO - [Pic] fonction retirer utilisée au temps 8.03371000289917
2023-10-06 09:16:09,033 - INFO - [Pic] fonction ajouter utilisée au temps 9.034941911697388
2023-10-06 09:16:09,033 - INFO - [Serveur] fonction prendre_commande utilisée au temps 9.035419464111328
2023-10-06 09:16:09,033 - INFO - [Barman] fonction prepare utilisée au temps 9.03585147857666
2023-10-06 09:16:09,034 - INFO - [Bar] fonction ajouter utilisée au temps 9.036161184310913
2023-10-06 09:16:09,034 - INFO - [Pic] fonction retirer utilisée au temps 9.036382675170898
2023-10-06 09:16:10,035 - INFO - [Pic] fonction ajouter utilisée au temps 10.037303447723389
2023-10-06 09:16:10,035 - INFO - [Serveur] fonction prendre_commande utilisée au temps 10.037866353988647
2023-10-06 09:16:10,036 - INFO - [Barman] fonction prepare utilisée au temps 10.038358449935913
2023-10-06 09:16:10,036 - INFO - [Bar] fonction ajouter utilisée au temps 10.038676500320435
2023-10-06 09:16:10,037 - INFO - [Pic] fonction retirer utilisée au temps 10.03905177116394
2023-10-06 09:16:11,033 - INFO - [Bar] fonction retirer utilisée au temps 11.035085916519165
2023-10-06 09:16:11,033 - INFO - [Serveur] fonction servir utilisée au temps 11.035600900650024
2023-10-06 09:16:11,037 - INFO - [Pic] fonction ajouter utilisée au temps 11.039736032485962
2023-10-06 09:16:11,038 - INFO - [Barman] fonction prepare utilisée au temps 11.040438175201416
2023-10-06 09:16:11,038 - INFO - [Bar] fonction ajouter utilisée au temps 11.040897369384766
2023-10-06 09:16:11,039 - INFO - [Pic] fonction retirer utilisée au temps 11.041189432144165
2023-10-06 09:16:12,036 - INFO - [Bar] fonction retirer utilisée au temps 12.038172721862793
2023-10-06 09:16:12,036 - INFO - [Serveur] fonction servir utilisée au temps 12.038774013519287
2023-10-06 09:16:12,040 - INFO - [Barman] fonction prepare utilisée au temps 12.042781114578247
2023-10-06 09:16:12,041 - INFO - [Bar] fonction ajouter utilisée au temps 12.043297290802002
2023-10-06 09:16:13,039 - INFO - [Bar] fonction retirer utilisée au temps 13.041174411773682
2023-10-06 09:16:13,039 - INFO - [Serveur] fonction servir utilisée au temps 13.04164981842041
2023-10-06 09:16:14,042 - INFO - [Bar] fonction retirer utilisée au temps 14.044217348098755
2023-10-06 09:16:14,043 - INFO - [Serveur] fonction servir utilisée au temps 14.045028448104858
2023-10-06 09:16:34,013 - ERROR - Task exception was never retrieved
future: <Task finished name='Task-3' coro=<Serveur.servir() done, defined at /home/ibotcazou/Bureau/Master_data_science/Master2_datascience/Informatique_charbonel/probleme_bar_cocktails/V2_asyncio/bar_asyncio.py:134> exception=SystemExit()>
Traceback (most recent call last):
  File "/usr/lib/python3.10/asyncio/runners.py", line 44, in run
    return loop.run_until_complete(main)
  File "/usr/lib/python3.10/asyncio/base_events.py", line 636, in run_until_complete
    self.run_forever()
  File "/usr/lib/python3.10/asyncio/base_events.py", line 603, in run_forever
    self._run_once()
  File "/usr/lib/python3.10/asyncio/base_events.py", line 1871, in _run_once
    event_list = self._selector.select(timeout)
  File "/usr/lib/python3.10/selectors.py", line 469, in select
    fd_event_list = self._selector.poll(timeout, max_ev)
KeyboardInterrupt

During handling of the above exception, another exception occurred:

Traceback (most recent call last):
  File "/home/ibotcazou/Bureau/Master_data_science/Master2_datascience/Informatique_charbonel/probleme_bar_cocktails/V2_asyncio/bar_asyncio.py", line 143, in servir
    await asyncio.sleep(self.bar.tp + self.pic.tc ) # Attendre un peu la commande va arriver sur le bar
  File "/usr/lib/python3.10/asyncio/tasks.py", line 605, in sleep
    return await future
asyncio.exceptions.CancelledError

During handling of the above exception, another exception occurred:

Traceback (most recent call last):
  File "/usr/lib/python3.10/asyncio/runners.py", line 47, in run
    _cancel_all_tasks(loop)
  File "/usr/lib/python3.10/asyncio/runners.py", line 63, in _cancel_all_tasks
    loop.run_until_complete(tasks.gather(*to_cancel, return_exceptions=True))
  File "/usr/lib/python3.10/asyncio/base_events.py", line 636, in run_until_complete
    self.run_forever()
  File "/usr/lib/python3.10/asyncio/base_events.py", line 603, in run_forever
    self._run_once()
  File "/usr/lib/python3.10/asyncio/base_events.py", line 1909, in _run_once
    handle._run()
  File "/usr/lib/python3.10/asyncio/events.py", line 80, in _run
    self._context.run(self._callback, *self._args)
  File "/home/ibotcazou/Bureau/Master_data_science/Master2_datascience/Informatique_charbonel/probleme_bar_cocktails/V2_asyncio/bar_asyncio.py", line 156, in servir
    sys.exit()
SystemExit
