2023-10-06 08:45:53,388 - DEBUG - Using selector: EpollSelector
2023-10-06 08:46:03,268 - INFO - [Serveur] fonction prendre_commande utilisée au temps 9.87992811203003
2023-10-06 08:46:05,271 - INFO - [Pic] fonction ajouter utilisée au temps 11.88302206993103
2023-10-06 08:46:05,272 - INFO - [Serveur] fonction prendre_commande utilisée au temps 11.883840322494507
2023-10-06 08:46:05,272 - INFO - [Pic] fonction retirer utilisée au temps 11.88448166847229
2023-10-06 08:46:06,273 - INFO - [Barman] fonction prepare utilisée au temps 12.885690450668335
2023-10-06 08:46:06,274 - INFO - [Bar] fonction ajouter utilisée au temps 12.885839939117432
2023-10-06 08:46:07,274 - INFO - [Pic] fonction ajouter utilisée au temps 13.88663387298584
2023-10-06 08:46:07,275 - INFO - [Serveur] fonction prendre_commande utilisée au temps 13.88740873336792
2023-10-06 08:46:08,276 - INFO - [Pic] fonction retirer utilisée au temps 14.888176918029785
2023-10-06 08:46:09,271 - INFO - [Bar] fonction retirer utilisée au temps 15.88318157196045
2023-10-06 08:46:09,271 - INFO - [Serveur] fonction servir utilisée au temps 15.88374638557434
2023-10-06 08:46:09,276 - INFO - [Pic] fonction ajouter utilisée au temps 15.888648271560669
2023-10-06 08:46:09,277 - INFO - [Serveur] fonction prendre_commande utilisée au temps 15.889248609542847
2023-10-06 08:46:09,278 - INFO - [Barman] fonction prepare utilisée au temps 15.889819383621216
2023-10-06 08:46:09,278 - INFO - [Bar] fonction ajouter utilisée au temps 15.890174627304077
2023-10-06 08:46:09,278 - INFO - [Pic] fonction retirer utilisée au temps 15.89063286781311
2023-10-06 08:46:10,280 - INFO - [Barman] fonction prepare utilisée au temps 16.892608880996704
2023-10-06 08:46:10,281 - INFO - [Bar] fonction ajouter utilisée au temps 16.89306092262268
2023-10-06 08:46:11,274 - INFO - [Bar] fonction retirer utilisée au temps 17.886075496673584
2023-10-06 08:46:11,274 - INFO - [Serveur] fonction servir utilisée au temps 17.886669635772705
2023-10-06 08:46:11,278 - INFO - [Pic] fonction ajouter utilisée au temps 17.890502452850342
2023-10-06 08:46:12,283 - INFO - [Pic] fonction retirer utilisée au temps 18.895467042922974
2023-10-06 08:46:13,277 - INFO - [Bar] fonction retirer utilisée au temps 19.888920783996582
2023-10-06 08:46:13,278 - INFO - [Serveur] fonction servir utilisée au temps 19.889787673950195
2023-10-06 08:46:13,285 - INFO - [Barman] fonction prepare utilisée au temps 19.896904945373535
2023-10-06 08:46:13,285 - INFO - [Bar] fonction ajouter utilisée au temps 19.89756441116333
2023-10-06 08:46:15,281 - INFO - [Bar] fonction retirer utilisée au temps 21.893736362457275
2023-10-06 08:46:15,282 - INFO - [Serveur] fonction servir utilisée au temps 21.894394636154175
2023-10-06 08:47:21,780 - ERROR - Task exception was never retrieved
future: <Task finished name='Task-3' coro=<Serveur.servir() done, defined at /home/ibotcazou/Bureau/Master_data_science/Master2_datascience/Informatique_charbonel/probleme_bar_cocktails/V2_asyncio/bar_asyncio.py:134> exception=SystemExit()>
Traceback (most recent call last):
  File "/usr/lib/python3.10/asyncio/runners.py", line 44, in run
    return loop.run_until_complete(main)
  File "/usr/lib/python3.10/asyncio/base_events.py", line 636, in run_until_complete
    self.run_forever()
  File "/usr/lib/python3.10/asyncio/base_events.py", line 603, in run_forever
    self._run_once()
  File "/usr/lib/python3.10/asyncio/base_events.py", line 1871, in _run_once
    event_list = self._selector.select(timeout)
  File "/usr/lib/python3.10/selectors.py", line 469, in select
    fd_event_list = self._selector.poll(timeout, max_ev)
KeyboardInterrupt

During handling of the above exception, another exception occurred:

Traceback (most recent call last):
  File "/home/ibotcazou/Bureau/Master_data_science/Master2_datascience/Informatique_charbonel/probleme_bar_cocktails/V2_asyncio/bar_asyncio.py", line 140, in servir
    await asyncio.sleep(self.bar.tp + self.pic.tc ) # Attendre un peu la commande va arriver sur le bar
  File "/usr/lib/python3.10/asyncio/tasks.py", line 605, in sleep
    return await future
asyncio.exceptions.CancelledError

During handling of the above exception, another exception occurred:

Traceback (most recent call last):
  File "/usr/lib/python3.10/asyncio/runners.py", line 47, in run
    _cancel_all_tasks(loop)
  File "/usr/lib/python3.10/asyncio/runners.py", line 63, in _cancel_all_tasks
    loop.run_until_complete(tasks.gather(*to_cancel, return_exceptions=True))
  File "/usr/lib/python3.10/asyncio/base_events.py", line 636, in run_until_complete
    self.run_forever()
  File "/usr/lib/python3.10/asyncio/base_events.py", line 603, in run_forever
    self._run_once()
  File "/usr/lib/python3.10/asyncio/base_events.py", line 1909, in _run_once
    handle._run()
  File "/usr/lib/python3.10/asyncio/events.py", line 80, in _run
    self._context.run(self._callback, *self._args)
  File "/home/ibotcazou/Bureau/Master_data_science/Master2_datascience/Informatique_charbonel/probleme_bar_cocktails/V2_asyncio/bar_asyncio.py", line 151, in servir
    sys.exit()
SystemExit
