2023-10-04 20:23:58,351 - DEBUG - Using selector: EpollSelector
2023-10-04 20:24:11,626 - INFO - [Serveur] fonction prendre_commande utilisée au temps 13.275056600570679
2023-10-04 20:24:14,631 - INFO - [Pic] fonction ajouter utilisée au temps 16.279555320739746
2023-10-04 20:24:14,631 - INFO - [Serveur] fonction prendre_commande utilisée au temps 16.280155181884766
2023-10-04 20:24:14,632 - INFO - [Pic] fonction retirer utilisée au temps 16.28060007095337
2023-10-04 20:24:14,733 - INFO - [Barman] fonction prepare utilisée au temps 16.381646394729614
2023-10-04 20:24:14,733 - INFO - [Bar] fonction ajouter utilisée au temps 16.381789207458496
2023-10-04 20:24:17,635 - INFO - [Pic] fonction ajouter utilisée au temps 19.28428888320923
2023-10-04 20:24:17,636 - INFO - [Serveur] fonction prendre_commande utilisée au temps 19.28494930267334
2023-10-04 20:24:17,734 - INFO - [Pic] fonction retirer utilisée au temps 19.38298988342285
2023-10-04 20:24:17,829 - INFO - [Bar] fonction retirer utilisée au temps 19.477632761001587
2023-10-04 20:24:17,829 - INFO - [Serveur] fonction servir utilisée au temps 19.478142023086548
2023-10-04 20:24:17,835 - INFO - [Barman] fonction prepare utilisée au temps 19.484134912490845
2023-10-04 20:24:17,836 - INFO - [Bar] fonction ajouter utilisée au temps 19.484659671783447
2023-10-04 20:24:18,331 - INFO - [Bar] fonction retirer utilisée au temps 19.98015284538269
2023-10-04 20:24:18,332 - INFO - [Serveur] fonction servir utilisée au temps 19.980803728103638
2023-10-04 20:24:18,939 - ERROR - Task exception was never retrieved
future: <Task finished name='Task-1' coro=<main() done, defined at /home/ibotcazou/Bureau/Master_data_science/Master2_datascience/Informatique_charbonel/probleme_bar_cocktails/V2_asyncio/./cocktail_asyncio.py:8> exception=SystemExit()>
Traceback (most recent call last):
  File "/usr/lib/python3.10/asyncio/runners.py", line 47, in run
    _cancel_all_tasks(loop)
  File "/usr/lib/python3.10/asyncio/runners.py", line 63, in _cancel_all_tasks
    loop.run_until_complete(tasks.gather(*to_cancel, return_exceptions=True))
  File "/usr/lib/python3.10/asyncio/base_events.py", line 636, in run_until_complete
    self.run_forever()
  File "/usr/lib/python3.10/asyncio/base_events.py", line 603, in run_forever
    self._run_once()
  File "/usr/lib/python3.10/asyncio/base_events.py", line 1909, in _run_once
    handle._run()
  File "/usr/lib/python3.10/asyncio/events.py", line 80, in _run
    self._context.run(self._callback, *self._args)
  File "/home/ibotcazou/Bureau/Master_data_science/Master2_datascience/Informatique_charbonel/probleme_bar_cocktails/V2_asyncio/./cocktail_asyncio.py", line 34, in main
    await asyncio.gather(*tasks3) #gère la concurrence
  File "/usr/lib/python3.10/asyncio/runners.py", line 44, in run
    return loop.run_until_complete(main)
  File "/usr/lib/python3.10/asyncio/base_events.py", line 636, in run_until_complete
    self.run_forever()
  File "/usr/lib/python3.10/asyncio/base_events.py", line 603, in run_forever
    self._run_once()
  File "/usr/lib/python3.10/asyncio/base_events.py", line 1909, in _run_once
    handle._run()
  File "/usr/lib/python3.10/asyncio/events.py", line 80, in _run
    self._context.run(self._callback, *self._args)
  File "/home/ibotcazou/Bureau/Master_data_science/Master2_datascience/Informatique_charbonel/probleme_bar_cocktails/V2_asyncio/bar_asyncio.py", line 156, in servir
    sys.exit()
SystemExit
